[2023-07-25 15:34:01,704: INFO: __init__: logging has started]
[2023-07-26 13:24:15,366: INFO: main: >>>>>> stage Data Ingestion stage started <<<<<<]
[2023-07-26 13:24:15,371: INFO: common: yaml file: config\config.yaml loaded successfully]
[2023-07-26 13:24:15,376: INFO: common: yaml file: params.yaml loaded successfully]
[2023-07-26 13:24:15,377: ERROR: main: yaml file is empty]
Traceback (most recent call last):
  File "d:\cnnclassification\src\cnnClassifier\utils\common.py", line 34, in read_yaml
    return ConfigBox(content)
           ^^^^^^^^^^^^^^^^^^
  File "box\box.py", line 279, in box.box.Box.__init__
box.exceptions.BoxValueError: Cannot extrapolate Box from string

During handling of the above exception, another exception occurred:

Traceback (most recent call last):
  File "D:\cnnClassification\main.py", line 8, in <module>
    data_ingestion.main()
  File "d:\cnnclassification\src\cnnClassifier\pipeline\stage_01_data_ingestion.py", line 11, in main
    config = ConfigurationManager()
             ^^^^^^^^^^^^^^^^^^^^^^
  File "d:\cnnclassification\src\cnnClassifier\config\configuaration.py", line 15, in __init__
    self.params = read_yaml(params_filepath)
                  ^^^^^^^^^^^^^^^^^^^^^^^^^^
  File "C:\Users\shash\anaconda3\envs\myenv\Lib\site-packages\ensure\main.py", line 849, in __call__
    return_val = self.f(*args, **kwargs)
                 ^^^^^^^^^^^^^^^^^^^^^^^
  File "d:\cnnclassification\src\cnnClassifier\utils\common.py", line 36, in read_yaml
    raise ValueError("yaml file is empty")
ValueError: yaml file is empty
[2023-07-26 13:25:09,024: INFO: main: >>>>>> stage Data Ingestion stage started <<<<<<]
[2023-07-26 13:25:09,027: INFO: common: yaml file: config\config.yaml loaded successfully]
[2023-07-26 13:25:09,029: INFO: common: yaml file: params.yaml loaded successfully]
[2023-07-26 13:25:09,029: ERROR: main: yaml file is empty]
Traceback (most recent call last):
  File "d:\cnnclassification\src\cnnClassifier\utils\common.py", line 34, in read_yaml
    return ConfigBox(content)
           ^^^^^^^^^^^^^^^^^^
  File "box\box.py", line 279, in box.box.Box.__init__
box.exceptions.BoxValueError: Cannot extrapolate Box from string

During handling of the above exception, another exception occurred:

Traceback (most recent call last):
  File "D:\cnnClassification\main.py", line 8, in <module>
    data_ingestion.main()
  File "d:\cnnclassification\src\cnnClassifier\pipeline\stage_01_data_ingestion.py", line 11, in main
    config = ConfigurationManager()
             ^^^^^^^^^^^^^^^^^^^^^^
  File "d:\cnnclassification\src\cnnClassifier\config\configuaration.py", line 15, in __init__
    self.params = read_yaml(params_filepath)
                  ^^^^^^^^^^^^^^^^^^^^^^^^^^
  File "C:\Users\shash\anaconda3\envs\myenv\Lib\site-packages\ensure\main.py", line 849, in __call__
    return_val = self.f(*args, **kwargs)
                 ^^^^^^^^^^^^^^^^^^^^^^^
  File "d:\cnnclassification\src\cnnClassifier\utils\common.py", line 36, in read_yaml
    raise ValueError("yaml file is empty")
ValueError: yaml file is empty
[2023-07-26 17:29:11,025: INFO: main: >>>>>> stage Data Ingestion stage started <<<<<<]
[2023-07-26 17:29:11,052: INFO: common: yaml file: config\config.yaml loaded successfully]
[2023-07-26 17:29:11,067: INFO: common: yaml file: params.yaml loaded successfully]
[2023-07-26 17:29:11,068: ERROR: main: yaml file is empty]
Traceback (most recent call last):
  File "d:\cnnclassification\src\cnnClassifier\utils\common.py", line 34, in read_yaml
    return ConfigBox(content)
           ^^^^^^^^^^^^^^^^^^
  File "box\box.py", line 279, in box.box.Box.__init__
box.exceptions.BoxValueError: Cannot extrapolate Box from string

During handling of the above exception, another exception occurred:

Traceback (most recent call last):
  File "D:\cnnClassification\main.py", line 8, in <module>
    data_ingestion.main()
  File "d:\cnnclassification\src\cnnClassifier\pipeline\stage_01_data_ingestion.py", line 11, in main
    config = ConfigurationManager()
             ^^^^^^^^^^^^^^^^^^^^^^
  File "d:\cnnclassification\src\cnnClassifier\config\configuaration.py", line 16, in __init__
    self.params = read_yaml(params_filepath)
                  ^^^^^^^^^^^^^^^^^^^^^^^^^^
  File "C:\Users\shash\anaconda3\envs\myenv\Lib\site-packages\ensure\main.py", line 849, in __call__
    return_val = self.f(*args, **kwargs)
                 ^^^^^^^^^^^^^^^^^^^^^^^
  File "d:\cnnclassification\src\cnnClassifier\utils\common.py", line 36, in read_yaml
    raise ValueError("yaml file is empty")
ValueError: yaml file is empty
[2023-07-26 17:35:50,176: INFO: main: >>>>>> stage Data Ingestion stage started <<<<<<]
[2023-07-26 17:35:50,179: INFO: common: yaml file: config\config.yaml loaded successfully]
[2023-07-26 17:35:50,198: INFO: common: yaml file: params.yaml loaded successfully]
[2023-07-26 17:35:50,201: INFO: common: created directory at: artifacts]
[2023-07-26 17:35:50,202: INFO: common: created directory at: artifacts/data_ingestion]
[2023-07-26 17:35:50,203: INFO: data_ingestion: Trying to download file...]
[2023-07-26 17:36:17,771: INFO: data_ingestion: artifacts/data_ingestion/data.zip download! with following info: 
Connection: close
Content-Length: 22329406
Cache-Control: max-age=300
Content-Security-Policy: default-src 'none'; style-src 'unsafe-inline'; sandbox
Content-Type: application/zip
ETag: "e33c4dcc8f22340234fac4b9da4a20b304912be521f658008139809163a077ea"
Strict-Transport-Security: max-age=31536000
X-Content-Type-Options: nosniff
X-Frame-Options: deny
X-XSS-Protection: 1; mode=block
X-GitHub-Request-Id: CAB0:69BED:123692:1961C9:64C10C20
Accept-Ranges: bytes
Date: Wed, 26 Jul 2023 12:05:53 GMT
Via: 1.1 varnish
X-Served-By: cache-ccu830042-CCU
X-Cache: MISS
X-Cache-Hits: 0
X-Timer: S1690373152.262100,VS0,VE1668
Vary: Authorization,Accept-Encoding,Origin
Access-Control-Allow-Origin: *
Cross-Origin-Resource-Policy: cross-origin
X-Fastly-Request-ID: e157e0b118ee8d19808ed59a88a573a02a623d0f
Expires: Wed, 26 Jul 2023 12:10:53 GMT
Source-Age: 1

]
[2023-07-26 17:36:17,779: INFO: data_ingestion: unzipping file and removing unawanted files]
[2023-07-26 17:36:18,009: INFO: data_ingestion: removing file:artifacts/data_ingestion\PetImages/Dog/11702.jpg of size: ~ 0 KB]
[2023-07-26 17:36:18,210: INFO: main: >>>>>> stage Data Ingestion stage completed <<<<<<

x==========x]
[2023-07-26 21:42:28,052: INFO: main: >>>>>> stage Data Ingestion stage started <<<<<<]
[2023-07-26 21:42:28,099: INFO: common: yaml file: config\config.yaml loaded successfully]
[2023-07-26 21:42:28,104: INFO: common: yaml file: params.yaml loaded successfully]
[2023-07-26 21:42:28,106: INFO: common: created directory at: artifacts]
[2023-07-26 21:42:28,107: INFO: common: created directory at: artifacts/data_ingestion]
[2023-07-26 21:42:28,108: INFO: data_ingestion: Trying to download file...]
[2023-07-26 21:43:20,281: INFO: data_ingestion: artifacts/data_ingestion/data.zip download! with following info: 
Connection: close
Content-Length: 22329406
Cache-Control: max-age=300
Content-Security-Policy: default-src 'none'; style-src 'unsafe-inline'; sandbox
Content-Type: application/zip
ETag: "e33c4dcc8f22340234fac4b9da4a20b304912be521f658008139809163a077ea"
Strict-Transport-Security: max-age=31536000
X-Content-Type-Options: nosniff
X-Frame-Options: deny
X-XSS-Protection: 1; mode=block
X-GitHub-Request-Id: 6172:41A8:14702:17F01:64C145EC
Accept-Ranges: bytes
Date: Wed, 26 Jul 2023 16:12:30 GMT
Via: 1.1 varnish
X-Served-By: cache-bom4739-BOM
X-Cache: MISS
X-Cache-Hits: 0
X-Timer: S1690387949.949916,VS0,VE1802
Vary: Authorization,Accept-Encoding,Origin
Access-Control-Allow-Origin: *
Cross-Origin-Resource-Policy: cross-origin
X-Fastly-Request-ID: b0197a5d19159b10ecd8a476117282940f1b36c2
Expires: Wed, 26 Jul 2023 16:17:30 GMT
Source-Age: 1

]
[2023-07-26 21:43:20,289: INFO: data_ingestion: unzipping file and removing unawanted files]
[2023-07-26 21:43:20,629: INFO: data_ingestion: removing file:artifacts/data_ingestion\PetImages/Dog/11702.jpg of size: ~ 0 KB]
[2023-07-26 21:43:20,980: INFO: main: >>>>>> stage Data Ingestion stage completed <<<<<<

x==========x]
[2023-07-26 21:43:20,988: INFO: main: >>>>>> stage Prepare Base Model started <<<<<<]
[2023-07-26 21:43:21,002: INFO: common: yaml file: config\config.yaml loaded successfully]
[2023-07-26 21:43:21,007: INFO: common: yaml file: params.yaml loaded successfully]
[2023-07-26 21:43:21,008: INFO: common: created directory at: artifacts]
[2023-07-26 21:43:21,008: ERROR: main: 'ConfigurationManager' object has no attribute 'get_prepare_base_model_config']
Traceback (most recent call last):
  File "D:\cnnClassification\main.py", line 19, in <module>
    prepare_base_model.main()
  File "d:\cnnclassification\src\cnnClassifier\pipeline\stage_02_prepare_base_model.py", line 12, in main
    prepare_base_model_config = config.get_prepare_base_model_config()
                                ^^^^^^^^^^^^^^^^^^^^^^^^^^^^^^^^^^^^
AttributeError: 'ConfigurationManager' object has no attribute 'get_prepare_base_model_config'
[2023-07-26 21:46:55,631: INFO: main: >>>>>> stage Data Ingestion stage started <<<<<<]
[2023-07-26 21:46:55,637: INFO: common: yaml file: config\config.yaml loaded successfully]
[2023-07-26 21:46:55,643: INFO: common: yaml file: params.yaml loaded successfully]
[2023-07-26 21:46:55,646: INFO: common: created directory at: artifacts]
[2023-07-26 21:46:55,647: INFO: common: created directory at: artifacts/data_ingestion]
[2023-07-26 21:46:55,647: INFO: data_ingestion: Trying to download file...]
[2023-07-26 21:46:55,648: INFO: data_ingestion: File already exists of size: ~ 21806 KB]
[2023-07-26 21:46:55,649: INFO: data_ingestion: unzipping file and removing unawanted files]
[2023-07-26 21:46:55,677: INFO: data_ingestion: removing file:artifacts/data_ingestion\PetImages/Dog/11702.jpg of size: ~ 0 KB]
[2023-07-26 21:46:55,702: INFO: main: >>>>>> stage Data Ingestion stage completed <<<<<<

x==========x]
[2023-07-26 21:46:55,703: INFO: main: >>>>>> stage Prepare Base Model started <<<<<<]
[2023-07-26 21:46:55,706: INFO: common: yaml file: config\config.yaml loaded successfully]
[2023-07-26 21:46:55,711: INFO: common: yaml file: params.yaml loaded successfully]
[2023-07-26 21:46:55,712: INFO: common: created directory at: artifacts]
[2023-07-26 21:46:55,713: ERROR: main: "'ConfigBox' object has no attribute 'prepare_base_model'"]
Traceback (most recent call last):
  File "box\box.py", line 587, in box.box.Box.__getitem__
KeyError: 'prepare_base_model'

The above exception was the direct cause of the following exception:

Traceback (most recent call last):
  File "box\box.py", line 620, in box.box.Box.__getattr__
  File "box\box.py", line 608, in box.box.Box.__getitem__
box.exceptions.BoxKeyError: "'prepare_base_model'"

During handling of the above exception, another exception occurred:

Traceback (most recent call last):
  File "box\box.py", line 622, in box.box.Box.__getattr__
AttributeError: 'ConfigBox' object has no attribute 'prepare_base_model'

The above exception was the direct cause of the following exception:

Traceback (most recent call last):
  File "box\config_box.py", line 28, in box.config_box.ConfigBox.__getattr__
  File "box\box.py", line 636, in box.box.Box.__getattr__
box.exceptions.BoxKeyError: "'ConfigBox' object has no attribute 'prepare_base_model'"

During handling of the above exception, another exception occurred:

Traceback (most recent call last):
  File "box\box.py", line 587, in box.box.Box.__getitem__
KeyError: 'prepare_base_model'

The above exception was the direct cause of the following exception:

Traceback (most recent call last):
  File "box\box.py", line 620, in box.box.Box.__getattr__
  File "box\box.py", line 608, in box.box.Box.__getitem__
box.exceptions.BoxKeyError: "'prepare_base_model'"

During handling of the above exception, another exception occurred:

Traceback (most recent call last):
  File "box\box.py", line 622, in box.box.Box.__getattr__
AttributeError: 'ConfigBox' object has no attribute 'prepare_base_model'

The above exception was the direct cause of the following exception:

Traceback (most recent call last):
  File "D:\cnnClassification\main.py", line 19, in <module>
    prepare_base_model.main()
  File "d:\cnnclassification\src\cnnClassifier\pipeline\stage_02_prepare_base_model.py", line 12, in main
    prepare_base_model_config = config.get_prepare_base_model_config()
                                ^^^^^^^^^^^^^^^^^^^^^^^^^^^^^^^^^^^^^^
  File "d:\cnnclassification\src\cnnClassifier\config\configuaration.py", line 38, in get_prepare_base_model_config
    config = self.config.prepare_base_model
             ^^^^^^^^^^^^^^^^^^^^^^^^^^^^^^
  File "box\config_box.py", line 30, in box.config_box.ConfigBox.__getattr__
  File "box\box.py", line 636, in box.box.Box.__getattr__
box.exceptions.BoxKeyError: "'ConfigBox' object has no attribute 'prepare_base_model'"
[2023-07-26 22:19:46,073: INFO: main: >>>>>> stage Data Ingestion stage started <<<<<<]
[2023-07-26 22:19:46,093: INFO: common: yaml file: config\config.yaml loaded successfully]
[2023-07-26 22:19:46,097: INFO: common: yaml file: params.yaml loaded successfully]
[2023-07-26 22:19:46,099: INFO: common: created directory at: artifacts]
[2023-07-26 22:19:46,100: INFO: common: created directory at: artifacts/data_ingestion]
[2023-07-26 22:19:46,100: INFO: data_ingestion: Trying to download file...]
[2023-07-26 22:20:08,076: ERROR: main: <urlopen error [WinError 10060] A connection attempt failed because the connected party did not properly respond after a period of time, or established connection failed because connected host has failed to respond>]
Traceback (most recent call last):
  File "C:\Users\shash\anaconda3\envs\myenv\Lib\urllib\request.py", line 1348, in do_open
    h.request(req.get_method(), req.selector, req.data, headers,
  File "C:\Users\shash\anaconda3\envs\myenv\Lib\http\client.py", line 1286, in request
    self._send_request(method, url, body, headers, encode_chunked)
  File "C:\Users\shash\anaconda3\envs\myenv\Lib\http\client.py", line 1332, in _send_request
    self.endheaders(body, encode_chunked=encode_chunked)
  File "C:\Users\shash\anaconda3\envs\myenv\Lib\http\client.py", line 1281, in endheaders
    self._send_output(message_body, encode_chunked=encode_chunked)
  File "C:\Users\shash\anaconda3\envs\myenv\Lib\http\client.py", line 1041, in _send_output
    self.send(msg)
  File "C:\Users\shash\anaconda3\envs\myenv\Lib\http\client.py", line 979, in send
    self.connect()
  File "C:\Users\shash\anaconda3\envs\myenv\Lib\http\client.py", line 1451, in connect
    super().connect()
  File "C:\Users\shash\anaconda3\envs\myenv\Lib\http\client.py", line 945, in connect
    self.sock = self._create_connection(
                ^^^^^^^^^^^^^^^^^^^^^^^^
  File "C:\Users\shash\anaconda3\envs\myenv\Lib\socket.py", line 851, in create_connection
    raise exceptions[0]
  File "C:\Users\shash\anaconda3\envs\myenv\Lib\socket.py", line 836, in create_connection
    sock.connect(sa)
TimeoutError: [WinError 10060] A connection attempt failed because the connected party did not properly respond after a period of time, or established connection failed because connected host has failed to respond

During handling of the above exception, another exception occurred:

Traceback (most recent call last):
  File "D:\cnnClassification\main.py", line 9, in <module>
    data_ingestion.main()
  File "d:\cnnclassification\src\cnnClassifier\pipeline\stage_01_data_ingestion.py", line 14, in main
    data_ingestion.download_file()
  File "d:\cnnclassification\src\cnnClassifier\components\data_ingestion.py", line 20, in download_file
    filename, headers = request.urlretrieve(
                        ^^^^^^^^^^^^^^^^^^^^
  File "C:\Users\shash\anaconda3\envs\myenv\Lib\urllib\request.py", line 241, in urlretrieve
    with contextlib.closing(urlopen(url, data)) as fp:
                            ^^^^^^^^^^^^^^^^^^
  File "C:\Users\shash\anaconda3\envs\myenv\Lib\urllib\request.py", line 216, in urlopen
    return opener.open(url, data, timeout)
           ^^^^^^^^^^^^^^^^^^^^^^^^^^^^^^^
  File "C:\Users\shash\anaconda3\envs\myenv\Lib\urllib\request.py", line 525, in open
    response = meth(req, response)
               ^^^^^^^^^^^^^^^^^^^
  File "C:\Users\shash\anaconda3\envs\myenv\Lib\urllib\request.py", line 634, in http_response
    response = self.parent.error(
               ^^^^^^^^^^^^^^^^^^
  File "C:\Users\shash\anaconda3\envs\myenv\Lib\urllib\request.py", line 557, in error
    result = self._call_chain(*args)
             ^^^^^^^^^^^^^^^^^^^^^^^
  File "C:\Users\shash\anaconda3\envs\myenv\Lib\urllib\request.py", line 496, in _call_chain
    result = func(*args)
             ^^^^^^^^^^^
  File "C:\Users\shash\anaconda3\envs\myenv\Lib\urllib\request.py", line 749, in http_error_302
    return self.parent.open(new, timeout=req.timeout)
           ^^^^^^^^^^^^^^^^^^^^^^^^^^^^^^^^^^^^^^^^^^
  File "C:\Users\shash\anaconda3\envs\myenv\Lib\urllib\request.py", line 519, in open
    response = self._open(req, data)
               ^^^^^^^^^^^^^^^^^^^^^
  File "C:\Users\shash\anaconda3\envs\myenv\Lib\urllib\request.py", line 536, in _open
    result = self._call_chain(self.handle_open, protocol, protocol +
             ^^^^^^^^^^^^^^^^^^^^^^^^^^^^^^^^^^^^^^^^^^^^^^^^^^^^^^^
  File "C:\Users\shash\anaconda3\envs\myenv\Lib\urllib\request.py", line 496, in _call_chain
    result = func(*args)
             ^^^^^^^^^^^
  File "C:\Users\shash\anaconda3\envs\myenv\Lib\urllib\request.py", line 1391, in https_open
    return self.do_open(http.client.HTTPSConnection, req,
           ^^^^^^^^^^^^^^^^^^^^^^^^^^^^^^^^^^^^^^^^^^^^^^
  File "C:\Users\shash\anaconda3\envs\myenv\Lib\urllib\request.py", line 1351, in do_open
    raise URLError(err)
urllib.error.URLError: <urlopen error [WinError 10060] A connection attempt failed because the connected party did not properly respond after a period of time, or established connection failed because connected host has failed to respond>
[2023-07-26 22:21:03,761: INFO: main: >>>>>> stage Data Ingestion stage started <<<<<<]
[2023-07-26 22:21:03,769: INFO: common: yaml file: config\config.yaml loaded successfully]
[2023-07-26 22:21:03,772: INFO: common: yaml file: params.yaml loaded successfully]
[2023-07-26 22:21:03,773: INFO: common: created directory at: artifacts]
[2023-07-26 22:21:03,774: INFO: common: created directory at: artifacts/data_ingestion]
[2023-07-26 22:21:03,775: INFO: data_ingestion: Trying to download file...]
[2023-07-26 22:21:25,063: ERROR: main: <urlopen error [WinError 10060] A connection attempt failed because the connected party did not properly respond after a period of time, or established connection failed because connected host has failed to respond>]
Traceback (most recent call last):
  File "C:\Users\shash\anaconda3\envs\myenv\Lib\urllib\request.py", line 1348, in do_open
    h.request(req.get_method(), req.selector, req.data, headers,
  File "C:\Users\shash\anaconda3\envs\myenv\Lib\http\client.py", line 1286, in request
    self._send_request(method, url, body, headers, encode_chunked)
  File "C:\Users\shash\anaconda3\envs\myenv\Lib\http\client.py", line 1332, in _send_request
    self.endheaders(body, encode_chunked=encode_chunked)
  File "C:\Users\shash\anaconda3\envs\myenv\Lib\http\client.py", line 1281, in endheaders
    self._send_output(message_body, encode_chunked=encode_chunked)
  File "C:\Users\shash\anaconda3\envs\myenv\Lib\http\client.py", line 1041, in _send_output
    self.send(msg)
  File "C:\Users\shash\anaconda3\envs\myenv\Lib\http\client.py", line 979, in send
    self.connect()
  File "C:\Users\shash\anaconda3\envs\myenv\Lib\http\client.py", line 1451, in connect
    super().connect()
  File "C:\Users\shash\anaconda3\envs\myenv\Lib\http\client.py", line 945, in connect
    self.sock = self._create_connection(
                ^^^^^^^^^^^^^^^^^^^^^^^^
  File "C:\Users\shash\anaconda3\envs\myenv\Lib\socket.py", line 851, in create_connection
    raise exceptions[0]
  File "C:\Users\shash\anaconda3\envs\myenv\Lib\socket.py", line 836, in create_connection
    sock.connect(sa)
TimeoutError: [WinError 10060] A connection attempt failed because the connected party did not properly respond after a period of time, or established connection failed because connected host has failed to respond

During handling of the above exception, another exception occurred:

Traceback (most recent call last):
  File "D:\cnnClassification\main.py", line 9, in <module>
    data_ingestion.main()
  File "d:\cnnclassification\src\cnnClassifier\pipeline\stage_01_data_ingestion.py", line 14, in main
    data_ingestion.download_file()
  File "d:\cnnclassification\src\cnnClassifier\components\data_ingestion.py", line 20, in download_file
    filename, headers = request.urlretrieve(
                        ^^^^^^^^^^^^^^^^^^^^
  File "C:\Users\shash\anaconda3\envs\myenv\Lib\urllib\request.py", line 241, in urlretrieve
    with contextlib.closing(urlopen(url, data)) as fp:
                            ^^^^^^^^^^^^^^^^^^
  File "C:\Users\shash\anaconda3\envs\myenv\Lib\urllib\request.py", line 216, in urlopen
    return opener.open(url, data, timeout)
           ^^^^^^^^^^^^^^^^^^^^^^^^^^^^^^^
  File "C:\Users\shash\anaconda3\envs\myenv\Lib\urllib\request.py", line 525, in open
    response = meth(req, response)
               ^^^^^^^^^^^^^^^^^^^
  File "C:\Users\shash\anaconda3\envs\myenv\Lib\urllib\request.py", line 634, in http_response
    response = self.parent.error(
               ^^^^^^^^^^^^^^^^^^
  File "C:\Users\shash\anaconda3\envs\myenv\Lib\urllib\request.py", line 557, in error
    result = self._call_chain(*args)
             ^^^^^^^^^^^^^^^^^^^^^^^
  File "C:\Users\shash\anaconda3\envs\myenv\Lib\urllib\request.py", line 496, in _call_chain
    result = func(*args)
             ^^^^^^^^^^^
  File "C:\Users\shash\anaconda3\envs\myenv\Lib\urllib\request.py", line 749, in http_error_302
    return self.parent.open(new, timeout=req.timeout)
           ^^^^^^^^^^^^^^^^^^^^^^^^^^^^^^^^^^^^^^^^^^
  File "C:\Users\shash\anaconda3\envs\myenv\Lib\urllib\request.py", line 519, in open
    response = self._open(req, data)
               ^^^^^^^^^^^^^^^^^^^^^
  File "C:\Users\shash\anaconda3\envs\myenv\Lib\urllib\request.py", line 536, in _open
    result = self._call_chain(self.handle_open, protocol, protocol +
             ^^^^^^^^^^^^^^^^^^^^^^^^^^^^^^^^^^^^^^^^^^^^^^^^^^^^^^^
  File "C:\Users\shash\anaconda3\envs\myenv\Lib\urllib\request.py", line 496, in _call_chain
    result = func(*args)
             ^^^^^^^^^^^
  File "C:\Users\shash\anaconda3\envs\myenv\Lib\urllib\request.py", line 1391, in https_open
    return self.do_open(http.client.HTTPSConnection, req,
           ^^^^^^^^^^^^^^^^^^^^^^^^^^^^^^^^^^^^^^^^^^^^^^
  File "C:\Users\shash\anaconda3\envs\myenv\Lib\urllib\request.py", line 1351, in do_open
    raise URLError(err)
urllib.error.URLError: <urlopen error [WinError 10060] A connection attempt failed because the connected party did not properly respond after a period of time, or established connection failed because connected host has failed to respond>
[2023-07-26 22:26:14,941: INFO: main: >>>>>> stage Data Ingestion stage started <<<<<<]
[2023-07-26 22:26:14,946: INFO: common: yaml file: config\config.yaml loaded successfully]
[2023-07-26 22:26:14,953: INFO: common: yaml file: params.yaml loaded successfully]
[2023-07-26 22:26:14,956: INFO: common: created directory at: artifacts]
[2023-07-26 22:26:14,957: INFO: common: created directory at: artifacts/data_ingestion]
[2023-07-26 22:26:14,958: INFO: data_ingestion: Trying to download file...]
[2023-07-26 22:26:37,073: ERROR: main: <urlopen error [WinError 10060] A connection attempt failed because the connected party did not properly respond after a period of time, or established connection failed because connected host has failed to respond>]
Traceback (most recent call last):
  File "C:\Users\shash\anaconda3\envs\myenv\Lib\urllib\request.py", line 1348, in do_open
    h.request(req.get_method(), req.selector, req.data, headers,
  File "C:\Users\shash\anaconda3\envs\myenv\Lib\http\client.py", line 1286, in request
    self._send_request(method, url, body, headers, encode_chunked)
  File "C:\Users\shash\anaconda3\envs\myenv\Lib\http\client.py", line 1332, in _send_request
    self.endheaders(body, encode_chunked=encode_chunked)
  File "C:\Users\shash\anaconda3\envs\myenv\Lib\http\client.py", line 1281, in endheaders
    self._send_output(message_body, encode_chunked=encode_chunked)
  File "C:\Users\shash\anaconda3\envs\myenv\Lib\http\client.py", line 1041, in _send_output
    self.send(msg)
  File "C:\Users\shash\anaconda3\envs\myenv\Lib\http\client.py", line 979, in send
    self.connect()
  File "C:\Users\shash\anaconda3\envs\myenv\Lib\http\client.py", line 1451, in connect
    super().connect()
  File "C:\Users\shash\anaconda3\envs\myenv\Lib\http\client.py", line 945, in connect
    self.sock = self._create_connection(
                ^^^^^^^^^^^^^^^^^^^^^^^^
  File "C:\Users\shash\anaconda3\envs\myenv\Lib\socket.py", line 851, in create_connection
    raise exceptions[0]
  File "C:\Users\shash\anaconda3\envs\myenv\Lib\socket.py", line 836, in create_connection
    sock.connect(sa)
TimeoutError: [WinError 10060] A connection attempt failed because the connected party did not properly respond after a period of time, or established connection failed because connected host has failed to respond

During handling of the above exception, another exception occurred:

Traceback (most recent call last):
  File "D:\cnnClassification\main.py", line 9, in <module>
    data_ingestion.main()
  File "d:\cnnclassification\src\cnnClassifier\pipeline\stage_01_data_ingestion.py", line 14, in main
    data_ingestion.download_file()
  File "d:\cnnclassification\src\cnnClassifier\components\data_ingestion.py", line 20, in download_file
    filename, headers = request.urlretrieve(
                        ^^^^^^^^^^^^^^^^^^^^
  File "C:\Users\shash\anaconda3\envs\myenv\Lib\urllib\request.py", line 241, in urlretrieve
    with contextlib.closing(urlopen(url, data)) as fp:
                            ^^^^^^^^^^^^^^^^^^
  File "C:\Users\shash\anaconda3\envs\myenv\Lib\urllib\request.py", line 216, in urlopen
    return opener.open(url, data, timeout)
           ^^^^^^^^^^^^^^^^^^^^^^^^^^^^^^^
  File "C:\Users\shash\anaconda3\envs\myenv\Lib\urllib\request.py", line 525, in open
    response = meth(req, response)
               ^^^^^^^^^^^^^^^^^^^
  File "C:\Users\shash\anaconda3\envs\myenv\Lib\urllib\request.py", line 634, in http_response
    response = self.parent.error(
               ^^^^^^^^^^^^^^^^^^
  File "C:\Users\shash\anaconda3\envs\myenv\Lib\urllib\request.py", line 557, in error
    result = self._call_chain(*args)
             ^^^^^^^^^^^^^^^^^^^^^^^
  File "C:\Users\shash\anaconda3\envs\myenv\Lib\urllib\request.py", line 496, in _call_chain
    result = func(*args)
             ^^^^^^^^^^^
  File "C:\Users\shash\anaconda3\envs\myenv\Lib\urllib\request.py", line 749, in http_error_302
    return self.parent.open(new, timeout=req.timeout)
           ^^^^^^^^^^^^^^^^^^^^^^^^^^^^^^^^^^^^^^^^^^
  File "C:\Users\shash\anaconda3\envs\myenv\Lib\urllib\request.py", line 519, in open
    response = self._open(req, data)
               ^^^^^^^^^^^^^^^^^^^^^
  File "C:\Users\shash\anaconda3\envs\myenv\Lib\urllib\request.py", line 536, in _open
    result = self._call_chain(self.handle_open, protocol, protocol +
             ^^^^^^^^^^^^^^^^^^^^^^^^^^^^^^^^^^^^^^^^^^^^^^^^^^^^^^^
  File "C:\Users\shash\anaconda3\envs\myenv\Lib\urllib\request.py", line 496, in _call_chain
    result = func(*args)
             ^^^^^^^^^^^
  File "C:\Users\shash\anaconda3\envs\myenv\Lib\urllib\request.py", line 1391, in https_open
    return self.do_open(http.client.HTTPSConnection, req,
           ^^^^^^^^^^^^^^^^^^^^^^^^^^^^^^^^^^^^^^^^^^^^^^
  File "C:\Users\shash\anaconda3\envs\myenv\Lib\urllib\request.py", line 1351, in do_open
    raise URLError(err)
urllib.error.URLError: <urlopen error [WinError 10060] A connection attempt failed because the connected party did not properly respond after a period of time, or established connection failed because connected host has failed to respond>
[2023-07-26 22:31:12,862: INFO: main: >>>>>> stage Data Ingestion stage started <<<<<<]
[2023-07-26 22:31:12,874: INFO: common: yaml file: config\config.yaml loaded successfully]
[2023-07-26 22:31:12,884: INFO: common: yaml file: params.yaml loaded successfully]
[2023-07-26 22:31:12,886: INFO: common: created directory at: artifacts]
[2023-07-26 22:31:12,887: INFO: common: created directory at: artifacts/data_ingestion]
[2023-07-26 22:31:12,889: INFO: data_ingestion: Trying to download file...]
[2023-07-26 22:31:28,299: INFO: data_ingestion: artifacts/data_ingestion/data.zip download! with following info: 
Connection: close
Content-Length: 22329406
Cache-Control: max-age=300
Content-Security-Policy: default-src 'none'; style-src 'unsafe-inline'; sandbox
Content-Type: application/zip
ETag: "e33c4dcc8f22340234fac4b9da4a20b304912be521f658008139809163a077ea"
Strict-Transport-Security: max-age=31536000
X-Content-Type-Options: nosniff
X-Frame-Options: deny
X-XSS-Protection: 1; mode=block
X-GitHub-Request-Id: 6172:41A8:14702:17F01:64C145EC
Accept-Ranges: bytes
Date: Wed, 26 Jul 2023 17:01:14 GMT
Via: 1.1 varnish
X-Served-By: cache-bom4729-BOM
X-Cache: HIT
X-Cache-Hits: 0
X-Timer: S1690390874.805090,VS0,VE350
Vary: Authorization,Accept-Encoding,Origin
Access-Control-Allow-Origin: *
Cross-Origin-Resource-Policy: cross-origin
X-Fastly-Request-ID: 0b00847f53606bac6e72f5abd4b99547196cf241
Expires: Wed, 26 Jul 2023 17:06:14 GMT
Source-Age: 0

]
[2023-07-26 22:31:28,305: INFO: data_ingestion: unzipping file and removing unawanted files]
[2023-07-26 22:31:28,528: INFO: data_ingestion: removing file:artifacts/data_ingestion\PetImages/Dog/11702.jpg of size: ~ 0 KB]
[2023-07-26 22:31:28,708: INFO: main: >>>>>> stage Data Ingestion stage completed <<<<<<

x==========x]
[2023-07-26 22:31:28,708: INFO: main: *******************]
[2023-07-26 22:31:28,708: INFO: main: >>>>>> stage Prepare Base Model started <<<<<<]
[2023-07-26 22:31:28,714: INFO: common: yaml file: config\config.yaml loaded successfully]
[2023-07-26 22:31:28,716: INFO: common: yaml file: params.yaml loaded successfully]
[2023-07-26 22:31:28,717: INFO: common: created directory at: artifacts]
[2023-07-26 22:31:28,718: INFO: common: created directory at: artifacts/prepare_base_model]
[2023-07-26 22:32:17,600: WARNING: saving_utils: Compiled the loaded model, but the compiled metrics have yet to be built. `model.compile_metrics` will be empty until you train or evaluate the model.]
[2023-07-26 22:32:17,954: INFO: main: >>>>>> stage Prepare Base Model completed <<<<<<

x==========x]
[2023-07-27 12:13:43,889: INFO: main: >>>>>> stage Data Ingestion stage started <<<<<<]
[2023-07-27 12:13:43,912: INFO: common: yaml file: config\config.yaml loaded successfully]
[2023-07-27 12:13:43,916: INFO: common: yaml file: params.yaml loaded successfully]
[2023-07-27 12:13:43,918: INFO: common: created directory at: artifacts]
[2023-07-27 12:13:43,919: INFO: common: created directory at: artifacts/data_ingestion]
[2023-07-27 12:13:43,919: INFO: data_ingestion: Trying to download file...]
[2023-07-27 12:15:32,894: INFO: data_ingestion: artifacts/data_ingestion/data.zip download! with following info: 
Connection: close
Content-Length: 22329406
Cache-Control: max-age=300
Content-Security-Policy: default-src 'none'; style-src 'unsafe-inline'; sandbox
Content-Type: application/zip
ETag: "e33c4dcc8f22340234fac4b9da4a20b304912be521f658008139809163a077ea"
Strict-Transport-Security: max-age=31536000
X-Content-Type-Options: nosniff
X-Frame-Options: deny
X-XSS-Protection: 1; mode=block
X-GitHub-Request-Id: C416:167279:6B744:99CA4:64C21221
Accept-Ranges: bytes
Date: Thu, 27 Jul 2023 06:43:47 GMT
Via: 1.1 varnish
X-Served-By: cache-ccu830039-CCU
X-Cache: MISS
X-Cache-Hits: 0
X-Timer: S1690440225.353148,VS0,VE1928
Vary: Authorization,Accept-Encoding,Origin
Access-Control-Allow-Origin: *
Cross-Origin-Resource-Policy: cross-origin
X-Fastly-Request-ID: 95538cfcbafc493079ad6af82245909688976390
Expires: Thu, 27 Jul 2023 06:48:47 GMT
Source-Age: 1

]
[2023-07-27 12:15:32,898: INFO: data_ingestion: unzipping file and removing unawanted files]
[2023-07-27 12:15:33,250: INFO: data_ingestion: removing file:artifacts/data_ingestion\PetImages/Dog/11702.jpg of size: ~ 0 KB]
[2023-07-27 12:15:33,552: INFO: main: >>>>>> stage Data Ingestion stage completed <<<<<<

x==========x]
[2023-07-27 12:15:33,553: INFO: main: *******************]
[2023-07-27 12:15:33,554: INFO: main: >>>>>> stage Prepare Base Model started <<<<<<]
[2023-07-27 12:15:33,558: INFO: common: yaml file: config\config.yaml loaded successfully]
[2023-07-27 12:15:33,562: INFO: common: yaml file: params.yaml loaded successfully]
[2023-07-27 12:15:33,564: INFO: common: created directory at: artifacts]
[2023-07-27 12:15:33,572: INFO: common: created directory at: artifacts/prepare_base_model]
[2023-07-27 12:15:34,975: WARNING: saving_utils: Compiled the loaded model, but the compiled metrics have yet to be built. `model.compile_metrics` will be empty until you train or evaluate the model.]
[2023-07-27 12:15:35,910: INFO: main: >>>>>> stage Prepare Base Model completed <<<<<<

x==========x]
[2023-07-27 12:15:35,913: INFO: main: *******************]
[2023-07-27 12:15:35,914: INFO: main: >>>>>> stage Training started <<<<<<]
[2023-07-27 12:15:35,927: INFO: common: yaml file: config\config.yaml loaded successfully]
[2023-07-27 12:15:35,933: INFO: common: yaml file: params.yaml loaded successfully]
[2023-07-27 12:15:35,936: INFO: common: created directory at: artifacts]
[2023-07-27 12:15:35,939: INFO: common: created directory at: artifacts\prepare_callbacks\checkpoint_dir]
[2023-07-27 12:15:35,945: INFO: common: created directory at: artifacts\prepare_callbacks\tensorboard_log_dir]
[2023-07-27 12:15:35,953: ERROR: main: 'WindowsPath' object has no attribute 'endswith']
Traceback (most recent call last):
  File "D:\cnnClassification\main.py", line 32, in <module>
    model_trainer.main()
  File "d:\cnnclassification\src\cnnClassifier\pipeline\stage_03_training.py", line 13, in main
    callback_list = prepare_callbacks.get_tb_ckpt_callbacks()
                    ^^^^^^^^^^^^^^^^^^^^^^^^^^^^^^^^^^^^^^^^^
  File "d:\cnnclassification\src\cnnClassifier\components\prepare_callback.py", line 33, in get_tb_ckpt_callbacks
    self._create_ckpt_callbacks
  File "d:\cnnclassification\src\cnnClassifier\components\prepare_callback.py", line 24, in _create_ckpt_callbacks
    return tf.keras.callbacks.ModelCheckpoint(
           ^^^^^^^^^^^^^^^^^^^^^^^^^^^^^^^^^^^
  File "C:\Users\shash\anaconda3\envs\myenv\Lib\site-packages\keras\src\callbacks.py", line 1369, in __init__
    if filepath and filepath.endswith(".keras") and options is not None:
                    ^^^^^^^^^^^^^^^^^
AttributeError: 'WindowsPath' object has no attribute 'endswith'
[2023-07-27 12:44:44,294: INFO: main: >>>>>> stage Data Ingestion stage started <<<<<<]
[2023-07-27 12:44:44,303: INFO: common: yaml file: config\config.yaml loaded successfully]
[2023-07-27 12:44:44,311: INFO: common: yaml file: params.yaml loaded successfully]
[2023-07-27 12:44:44,312: INFO: common: created directory at: artifacts]
[2023-07-27 12:44:44,313: INFO: common: created directory at: artifacts/data_ingestion]
[2023-07-27 12:44:44,313: INFO: data_ingestion: Trying to download file...]
[2023-07-27 12:44:44,314: INFO: data_ingestion: File already exists of size: ~ 21806 KB]
[2023-07-27 12:44:44,314: INFO: data_ingestion: unzipping file and removing unawanted files]
[2023-07-27 12:44:44,353: INFO: data_ingestion: removing file:artifacts/data_ingestion\PetImages/Dog/11702.jpg of size: ~ 0 KB]
[2023-07-27 12:44:44,378: INFO: main: >>>>>> stage Data Ingestion stage completed <<<<<<

x==========x]
[2023-07-27 12:44:44,379: INFO: main: *******************]
[2023-07-27 12:44:44,379: INFO: main: >>>>>> stage Prepare Base Model started <<<<<<]
[2023-07-27 12:44:44,382: INFO: common: yaml file: config\config.yaml loaded successfully]
[2023-07-27 12:44:44,383: INFO: common: yaml file: params.yaml loaded successfully]
[2023-07-27 12:44:44,384: INFO: common: created directory at: artifacts]
[2023-07-27 12:44:44,385: INFO: common: created directory at: artifacts/prepare_base_model]
[2023-07-27 12:44:45,396: WARNING: saving_utils: Compiled the loaded model, but the compiled metrics have yet to be built. `model.compile_metrics` will be empty until you train or evaluate the model.]
[2023-07-27 12:44:46,133: INFO: main: >>>>>> stage Prepare Base Model completed <<<<<<

x==========x]
[2023-07-27 12:44:46,133: INFO: main: *******************]
[2023-07-27 12:44:46,138: INFO: main: >>>>>> stage Training started <<<<<<]
[2023-07-27 12:44:46,143: INFO: common: yaml file: config\config.yaml loaded successfully]
[2023-07-27 12:44:46,147: INFO: common: yaml file: params.yaml loaded successfully]
[2023-07-27 12:44:46,149: INFO: common: created directory at: artifacts]
[2023-07-27 12:44:46,151: INFO: common: created directory at: artifacts\prepare_callbacks\checkpoint_dir]
[2023-07-27 12:44:46,154: INFO: common: created directory at: artifacts\prepare_callbacks\tensorboard_log_dir]
[2023-07-27 12:44:46,161: INFO: common: created directory at: artifacts\training]
[2023-07-27 12:46:02,781: INFO: main: >>>>>> stage Training completed <<<<<<

x==========x]
[2023-07-27 13:20:42,401: INFO: main: >>>>>> stage Data Ingestion stage started <<<<<<]
[2023-07-27 13:20:42,412: INFO: common: yaml file: config\config.yaml loaded successfully]
[2023-07-27 13:20:42,417: INFO: common: yaml file: params.yaml loaded successfully]
[2023-07-27 13:20:42,421: INFO: common: created directory at: artifacts]
[2023-07-27 13:20:42,422: INFO: common: created directory at: artifacts/data_ingestion]
[2023-07-27 13:20:42,423: INFO: data_ingestion: Trying to download file...]
[2023-07-27 13:20:42,423: INFO: data_ingestion: File already exists of size: ~ 21806 KB]
[2023-07-27 13:20:42,424: INFO: data_ingestion: unzipping file and removing unawanted files]
[2023-07-27 13:20:42,461: INFO: data_ingestion: removing file:artifacts/data_ingestion\PetImages/Dog/11702.jpg of size: ~ 0 KB]
[2023-07-27 13:20:42,485: INFO: main: >>>>>> stage Data Ingestion stage completed <<<<<<

x==========x]
[2023-07-27 13:20:42,485: INFO: main: *******************]
[2023-07-27 13:20:42,486: INFO: main: >>>>>> stage Prepare Base Model started <<<<<<]
[2023-07-27 13:20:42,490: INFO: common: yaml file: config\config.yaml loaded successfully]
[2023-07-27 13:20:42,494: INFO: common: yaml file: params.yaml loaded successfully]
[2023-07-27 13:20:42,495: INFO: common: created directory at: artifacts]
[2023-07-27 13:20:42,496: INFO: common: created directory at: artifacts/prepare_base_model]
[2023-07-27 13:20:43,376: WARNING: saving_utils: Compiled the loaded model, but the compiled metrics have yet to be built. `model.compile_metrics` will be empty until you train or evaluate the model.]
[2023-07-27 13:20:43,765: INFO: main: >>>>>> stage Prepare Base Model completed <<<<<<

x==========x]
[2023-07-27 13:20:43,766: INFO: main: *******************]
[2023-07-27 13:20:43,766: INFO: main: >>>>>> stage Training started <<<<<<]
[2023-07-27 13:20:43,771: INFO: common: yaml file: config\config.yaml loaded successfully]
[2023-07-27 13:20:43,775: INFO: common: yaml file: params.yaml loaded successfully]
[2023-07-27 13:20:43,776: INFO: common: created directory at: artifacts]
[2023-07-27 13:20:43,777: INFO: common: created directory at: artifacts\prepare_callbacks\checkpoint_dir]
[2023-07-27 13:20:43,778: INFO: common: created directory at: artifacts\prepare_callbacks\tensorboard_log_dir]
[2023-07-27 13:20:43,781: INFO: common: created directory at: artifacts\training]
[2023-07-27 13:21:53,619: INFO: main: >>>>>> stage Training completed <<<<<<

x==========x]
[2023-07-27 13:21:53,621: INFO: main: *******************]
[2023-07-27 13:21:53,622: INFO: main: >>>>>> stage Evaluation stage started <<<<<<]
[2023-07-27 13:21:53,630: INFO: common: yaml file: config\config.yaml loaded successfully]
[2023-07-27 13:21:53,639: INFO: common: yaml file: params.yaml loaded successfully]
[2023-07-27 13:21:53,646: INFO: common: created directory at: artifacts]
[2023-07-27 13:22:18,751: INFO: common: json file saved at: scores.json]
[2023-07-27 13:22:18,752: INFO: main: >>>>>> stage Evaluation stage completed <<<<<<

x==========x]
